Workbook

Sheet Parametre
A1: Tür | B1: s (sn/parça) | C1: P (süre payı) | D1: Bomba payı | E1: Çivi payı 1 | F1: Çivi payı 2 | G1: İlk deneme hedefi | H1: Near-miss hedefi
A2: Tanıtım | B2: 1.1 | C2: 2.2 | D2: 10 | E2: 0.225 | F2: 0.225 | G2: ≥ %95 | H2: %0–5
A3: Nefes | B3: 1 | C3: 2 | D3: 8 | E3: 0.225 | F3: 0.225 | G3: ≥ %90 | H3: %0–5
A4: Kolay | B4: 1 | C4: 2 | D4: 8 | E4: 0.225 | F4: 0.225 | G4: %85–95 | H4: %0–5
A5: Orta | B5: 1.1 | C5: 1.6 | D5: 8 | E5: 0.3 | F5: 0.3 | G5: %65–85 | H5: %5–15
A6: Zor | B6: 1.2 | C6: 1.3 | D6: 5 | E6: 0.275 | F6: 0.375 | G6: %40–60 | H6: %15–30
A7: Çok zor | B7: 1.3 | C7: 1.15 | D7: 2 | E7: 0.275 | F7: 0.375 | G7: %20–35 | H7: %30–50
A9: Kaynak: PRODUCT.md "Zorluk modeli (başlangıç değerleri)". Süre = ⌈gövde × s × P⌉₅, en fazla 75 sn; s yapıdan: 0,6 + 0,16 × hamle başına okuma (+0,1 bombalı, ilk bölümde 1,35).
A10: Fitil = en kısa kazma yolu + bomba payı. Çivi sayacı = gövde × pay (üst sınır %40). Medyan oyuncunun kalan süresi = 1 − gövde × s / süre; yıldız: ≥ %45 → 3, ≥ %20 → 2, altı 1.

Sheet Seviye
A1: Seviye | B1: Tür | C1: Gövde | D1: Hamle başına okuma | E1: Bomba | F1: En kısa kazma (en yakın bomba) | G1: İlk bölüm | H1: Çivi | I1: Mevcut süre | J1: s | K1: P | L1: Önerilen süre | M1: Önerilen fitil | N1: Çivi sayacı 1 | O1: Çivi sayacı 2 | P1: Medyan kalan süre | Q1: Medyan yıldız
A2: L01 | B2: Tanıtım | C2: 20 | D2: 2.434 | E2: 0 | G2: 1 | H2: 0 | I2: 60 | J2: =_xlfn.LET(_xlpm.r,D2,_xlpm.b,E2,_xlpm.f,G2,IF(_xlpm.f=1,1.35,0.6+0.16*_xlpm.r+IF(_xlpm.b>0,0.1,0))) | K2: =_xlfn.XLOOKUP(B2,Parametre!$A$2:$A$7,Parametre!$C$2:$C$7) | L2: =_xlfn.LET(_xlpm.g,C2,_xlpm.s,J2,_xlpm.p,K2,MIN(75,_xlfn.CEILING.MATH(_xlpm.g*_xlpm.s*_xlpm.p,5))) | M2: =IF(E2=0,"",F2+_xlfn.XLOOKUP(B2,Parametre!$A$2:$A$7,Parametre!$D$2:$D$7)) | N2: =_xlfn.LET(_xlpm.g,C2,_xlpm.k,_xlfn.XLOOKUP(B2,Parametre!$A$2:$A$7,Parametre!$E$2:$E$7),IF(H2<1,"",MAX(1,ROUND(_xlpm.g*_xlpm.k,0)))) | O2: =_xlfn.LET(_xlpm.g,C2,_xlpm.k,_xlfn.XLOOKUP(B2,Parametre!$A$2:$A$7,Parametre!$F$2:$F$7),IF(H2<2,"",MAX(1,ROUND(_xlpm.g*_xlpm.k,0)))) | P2: =_xlfn.LET(_xlpm.g,C2,_xlpm.s,J2,_xlpm.t,L2,1-_xlpm.g*_xlpm.s/_xlpm.t) | Q2: =_xlfn.LET(_xlpm.m,P2,IF(_xlpm.m>=0.45,3,IF(_xlpm.m>=0.2,2,1)))
A3: L02 | B3: Orta | C3: 25 | D3: 2.924 | E3: 0 | G3: 0 | H3: 0 | I3: 85 | J3: =_xlfn.LET(_xlpm.r,D3,_xlpm.b,E3,_xlpm.f,G3,IF(_xlpm.f=1,1.35,0.6+0.16*_xlpm.r+IF(_xlpm.b>0,0.1,0))) | K3: =_xlfn.XLOOKUP(B3,Parametre!$A$2:$A$7,Parametre!$C$2:$C$7) | L3: =_xlfn.LET(_xlpm.g,C3,_xlpm.s,J3,_xlpm.p,K3,MIN(75,_xlfn.CEILING.MATH(_xlpm.g*_xlpm.s*_xlpm.p,5))) | M3: =IF(E3=0,"",F3+_xlfn.XLOOKUP(B3,Parametre!$A$2:$A$7,Parametre!$D$2:$D$7)) | N3: =_xlfn.LET(_xlpm.g,C3,_xlpm.k,_xlfn.XLOOKUP(B3,Parametre!$A$2:$A$7,Parametre!$E$2:$E$7),IF(H3<1,"",MAX(1,ROUND(_xlpm.g*_xlpm.k,0)))) | O3: =_xlfn.LET(_xlpm.g,C3,_xlpm.k,_xlfn.XLOOKUP(B3,Parametre!$A$2:$A$7,Parametre!$F$2:$F$7),IF(H3<2,"",MAX(1,ROUND(_xlpm.g*_xlpm.k,0)))) | P3: =_xlfn.LET(_xlpm.g,C3,_xlpm.s,J3,_xlpm.t,L3,1-_xlpm.g*_xlpm.s/_xlpm.t) | Q3: =_xlfn.LET(_xlpm.m,P3,IF(_xlpm.m>=0.45,3,IF(_xlpm.m>=0.2,2,1)))
A4: L03 | B4: Kolay | C4: 25 | D4: 2.296 | E4: 0 | G4: 0 | H4: 0 | I4: 70 | J4: =_xlfn.LET(_xlpm.r,D4,_xlpm.b,E4,_xlpm.f,G4,IF(_xlpm.f=1,1.35,0.6+0.16*_xlpm.r+IF(_xlpm.b>0,0.1,0))) | K4: =_xlfn.XLOOKUP(B4,Parametre!$A$2:$A$7,Parametre!$C$2:$C$7) | L4: =_xlfn.LET(_xlpm.g,C4,_xlpm.s,J4,_xlpm.p,K4,MIN(75,_xlfn.CEILING.MATH(_xlpm.g*_xlpm.s*_xlpm.p,5))) | M4: =IF(E4=0,"",F4+_xlfn.XLOOKUP(B4,Parametre!$A$2:$A$7,Parametre!$D$2:$D$7)) | N4: =_xlfn.LET(_xlpm.g,C4,_xlpm.k,_xlfn.XLOOKUP(B4,Parametre!$A$2:$A$7,Parametre!$E$2:$E$7),IF(H4<1,"",MAX(1,ROUND(_xlpm.g*_xlpm.k,0)))) | O4: =_xlfn.LET(_xlpm.g,C4,_xlpm.k,_xlfn.XLOOKUP(B4,Parametre!$A$2:$A$7,Parametre!$F$2:$F$7),IF(H4<2,"",MAX(1,ROUND(_xlpm.g*_xlpm.k,0)))) | P4: =_xlfn.LET(_xlpm.g,C4,_xlpm.s,J4,_xlpm.t,L4,1-_xlpm.g*_xlpm.s/_xlpm.t) | Q4: =_xlfn.LET(_xlpm.m,P4,IF(_xlpm.m>=0.45,3,IF(_xlpm.m>=0.2,2,1)))
A5: L04 | B5: Orta | C5: 25 | D5: 2.863 | E5: 0 | G5: 0 | H5: 0 | I5: 80 | J5: =_xlfn.LET(_xlpm.r,D5,_xlpm.b,E5,_xlpm.f,G5,IF(_xlpm.f=1,1.35,0.6+0.16*_xlpm.r+IF(_xlpm.b>0,0.1,0))) | K5: =_xlfn.XLOOKUP(B5,Parametre!$A$2:$A$7,Parametre!$C$2:$C$7) | L5: =_xlfn.LET(_xlpm.g,C5,_xlpm.s,J5,_xlpm.p,K5,MIN(75,_xlfn.CEILING.MATH(_xlpm.g*_xlpm.s*_xlpm.p,5))) | M5: =IF(E5=0,"",F5+_xlfn.XLOOKUP(B5,Parametre!$A$2:$A$7,Parametre!$D$2:$D$7)) | N5: =_xlfn.LET(_xlpm.g,C5,_xlpm.k,_xlfn.XLOOKUP(B5,Parametre!$A$2:$A$7,Parametre!$E$2:$E$7),IF(H5<1,"",MAX(1,ROUND(_xlpm.g*_xlpm.k,0)))) | O5: =_xlfn.LET(_xlpm.g,C5,_xlpm.k,_xlfn.XLOOKUP(B5,Parametre!$A$2:$A$7,Parametre!$F$2:$F$7),IF(H5<2,"",MAX(1,ROUND(_xlpm.g*_xlpm.k,0)))) | P5: =_xlfn.LET(_xlpm.g,C5,_xlpm.s,J5,_xlpm.t,L5,1-_xlpm.g*_xlpm.s/_xlpm.t) | Q5: =_xlfn.LET(_xlpm.m,P5,IF(_xlpm.m>=0.45,3,IF(_xlpm.m>=0.2,2,1)))
A6: L05 | B6: Tanıtım | C6: 30 | D6: 2.663 | E6: 0 | G6: 0 | H6: 2 | I6: 95 | J6: =_xlfn.LET(_xlpm.r,D6,_xlpm.b,E6,_xlpm.f,G6,IF(_xlpm.f=1,1.35,0.6+0.16*_xlpm.r+IF(_xlpm.b>0,0.1,0))) | K6: =_xlfn.XLOOKUP(B6,Parametre!$A$2:$A$7,Parametre!$C$2:$C$7) | L6: =_xlfn.LET(_xlpm.g,C6,_xlpm.s,J6,_xlpm.p,K6,MIN(75,_xlfn.CEILING.MATH(_xlpm.g*_xlpm.s*_xlpm.p,5))) | M6: =IF(E6=0,"",F6+_xlfn.XLOOKUP(B6,Parametre!$A$2:$A$7,Parametre!$D$2:$D$7)) | N6: =_xlfn.LET(_xlpm.g,C6,_xlpm.k,_xlfn.XLOOKUP(B6,Parametre!$A$2:$A$7,Parametre!$E$2:$E$7),IF(H6<1,"",MAX(1,ROUND(_xlpm.g*_xlpm.k,0)))) | O6: =_xlfn.LET(_xlpm.g,C6,_xlpm.k,_xlfn.XLOOKUP(B6,Parametre!$A$2:$A$7,Parametre!$F$2:$F$7),IF(H6<2,"",MAX(1,ROUND(_xlpm.g*_xlpm.k,0)))) | P6: =_xlfn.LET(_xlpm.g,C6,_xlpm.s,J6,_xlpm.t,L6,1-_xlpm.g*_xlpm.s/_xlpm.t) | Q6: =_xlfn.LET(_xlpm.m,P6,IF(_xlpm.m>=0.45,3,IF(_xlpm.m>=0.2,2,1)))
A7: L06 | B7: Kolay | C7: 30 | D7: 2.545 | E7: 0 | G7: 0 | H7: 2 | I7: 90 | J7: =_xlfn.LET(_xlpm.r,D7,_xlpm.b,E7,_xlpm.f,G7,IF(_xlpm.f=1,1.35,0.6+0.16*_xlpm.r+IF(_xlpm.b>0,0.1,0))) | K7: =_xlfn.XLOOKUP(B7,Parametre!$A$2:$A$7,Parametre!$C$2:$C$7) | L7: =_xlfn.LET(_xlpm.g,C7,_xlpm.s,J7,_xlpm.p,K7,MIN(75,_xlfn.CEILING.MATH(_xlpm.g*_xlpm.s*_xlpm.p,5))) | M7: =IF(E7=0,"",F7+_xlfn.XLOOKUP(B7,Parametre!$A$2:$A$7,Parametre!$D$2:$D$7)) | N7: =_xlfn.LET(_xlpm.g,C7,_xlpm.k,_xlfn.XLOOKUP(B7,Parametre!$A$2:$A$7,Parametre!$E$2:$E$7),IF(H7<1,"",MAX(1,ROUND(_xlpm.g*_xlpm.k,0)))) | O7: =_xlfn.LET(_xlpm.g,C7,_xlpm.k,_xlfn.XLOOKUP(B7,Parametre!$A$2:$A$7,Parametre!$F$2:$F$7),IF(H7<2,"",MAX(1,ROUND(_xlpm.g*_xlpm.k,0)))) | P7: =_xlfn.LET(_xlpm.g,C7,_xlpm.s,J7,_xlpm.t,L7,1-_xlpm.g*_xlpm.s/_xlpm.t) | Q7: =_xlfn.LET(_xlpm.m,P7,IF(_xlpm.m>=0.45,3,IF(_xlpm.m>=0.2,2,1)))
A8: L07 | B8: Orta | C8: 30 | D8: 3.039 | E8: 0 | G8: 0 | H8: 3 | I8: 100 | J8: =_xlfn.LET(_xlpm.r,D8,_xlpm.b,E8,_xlpm.f,G8,IF(_xlpm.f=1,1.35,0.6+0.16*_xlpm.r+IF(_xlpm.b>0,0.1,0))) | K8: =_xlfn.XLOOKUP(B8,Parametre!$A$2:$A$7,Parametre!$C$2:$C$7) | L8: =_xlfn.LET(_xlpm.g,C8,_xlpm.s,J8,_xlpm.p,K8,MIN(75,_xlfn.CEILING.MATH(_xlpm.g*_xlpm.s*_xlpm.p,5))) | M8: =IF(E8=0,"",F8+_xlfn.XLOOKUP(B8,Parametre!$A$2:$A$7,Parametre!$D$2:$D$7)) | N8: =_xlfn.LET(_xlpm.g,C8,_xlpm.k,_xlfn.XLOOKUP(B8,Parametre!$A$2:$A$7,Parametre!$E$2:$E$7),IF(H8<1,"",MAX(1,ROUND(_xlpm.g*_xlpm.k,0)))) | O8: =_xlfn.LET(_xlpm.g,C8,_xlpm.k,_xlfn.XLOOKUP(B8,Parametre!$A$2:$A$7,Parametre!$F$2:$F$7),IF(H8<2,"",MAX(1,ROUND(_xlpm.g*_xlpm.k,0)))) | P8: =_xlfn.LET(_xlpm.g,C8,_xlpm.s,J8,_xlpm.t,L8,1-_xlpm.g*_xlpm.s/_xlpm.t) | Q8: =_xlfn.LET(_xlpm.m,P8,IF(_xlpm.m>=0.45,3,IF(_xlpm.m>=0.2,2,1)))
A9: L08 | B9: Orta | C9: 36 | D9: 2.754 | E9: 0 | G9: 0 | H9: 3 | I9: 115 | J9: =_xlfn.LET(_xlpm.r,D9,_xlpm.b,E9,_xlpm.f,G9,IF(_xlpm.f=1,1.35,0.6+0.16*_xlpm.r+IF(_xlpm.b>0,0.1,0))) | K9: =_xlfn.XLOOKUP(B9,Parametre!$A$2:$A$7,Parametre!$C$2:$C$7) | L9: =_xlfn.LET(_xlpm.g,C9,_xlpm.s,J9,_xlpm.p,K9,MIN(75,_xlfn.CEILING.MATH(_xlpm.g*_xlpm.s*_xlpm.p,5))) | M9: =IF(E9=0,"",F9+_xlfn.XLOOKUP(B9,Parametre!$A$2:$A$7,Parametre!$D$2:$D$7)) | N9: =_xlfn.LET(_xlpm.g,C9,_xlpm.k,_xlfn.XLOOKUP(B9,Parametre!$A$2:$A$7,Parametre!$E$2:$E$7),IF(H9<1,"",MAX(1,ROUND(_xlpm.g*_xlpm.k,0)))) | O9: =_xlfn.LET(_xlpm.g,C9,_xlpm.k,_xlfn.XLOOKUP(B9,Parametre!$A$2:$A$7,Parametre!$F$2:$F$7),IF(H9<2,"",MAX(1,ROUND(_xlpm.g*_xlpm.k,0)))) | P9: =_xlfn.LET(_xlpm.g,C9,_xlpm.s,J9,_xlpm.t,L9,1-_xlpm.g*_xlpm.s/_xlpm.t) | Q9: =_xlfn.LET(_xlpm.m,P9,IF(_xlpm.m>=0.45,3,IF(_xlpm.m>=0.2,2,1)))
A10: L09 | B10: Orta | C10: 36 | D10: 2.832 | E10: 0 | G10: 0 | H10: 3 | I10: 115 | J10: =_xlfn.LET(_xlpm.r,D10,_xlpm.b,E10,_xlpm.f,G10,IF(_xlpm.f=1,1.35,0.6+0.16*_xlpm.r+IF(_xlpm.b>0,0.1,0))) | K10: =_xlfn.XLOOKUP(B10,Parametre!$A$2:$A$7,Parametre!$C$2:$C$7) | L10: =_xlfn.LET(_xlpm.g,C10,_xlpm.s,J10,_xlpm.p,K10,MIN(75,_xlfn.CEILING.MATH(_xlpm.g*_xlpm.s*_xlpm.p,5))) | M10: =IF(E10=0,"",F10+_xlfn.XLOOKUP(B10,Parametre!$A$2:$A$7,Parametre!$D$2:$D$7)) | N10: =_xlfn.LET(_xlpm.g,C10,_xlpm.k,_xlfn.XLOOKUP(B10,Parametre!$A$2:$A$7,Parametre!$E$2:$E$7),IF(H10<1,"",MAX(1,ROUND(_xlpm.g*_xlpm.k,0)))) | O10: =_xlfn.LET(_xlpm.g,C10,_xlpm.k,_xlfn.XLOOKUP(B10,Parametre!$A$2:$A$7,Parametre!$F$2:$F$7),IF(H10<2,"",MAX(1,ROUND(_xlpm.g*_xlpm.k,0)))) | P10: =_xlfn.LET(_xlpm.g,C10,_xlpm.s,J10,_xlpm.t,L10,1-_xlpm.g*_xlpm.s/_xlpm.t) | Q10: =_xlfn.LET(_xlpm.m,P10,IF(_xlpm.m>=0.45,3,IF(_xlpm.m>=0.2,2,1)))
A11: L10 | B11: Orta | C11: 36 | D11: 2.8 | E11: 0 | G11: 0 | H11: 4 | I11: 115 | J11: =_xlfn.LET(_xlpm.r,D11,_xlpm.b,E11,_xlpm.f,G11,IF(_xlpm.f=1,1.35,0.6+0.16*_xlpm.r+IF(_xlpm.b>0,0.1,0))) | K11: =_xlfn.XLOOKUP(B11,Parametre!$A$2:$A$7,Parametre!$C$2:$C$7) | L11: =_xlfn.LET(_xlpm.g,C11,_xlpm.s,J11,_xlpm.p,K11,MIN(75,_xlfn.CEILING.MATH(_xlpm.g*_xlpm.s*_xlpm.p,5))) | M11: =IF(E11=0,"",F11+_xlfn.XLOOKUP(B11,Parametre!$A$2:$A$7,Parametre!$D$2:$D$7)) | N11: =_xlfn.LET(_xlpm.g,C11,_xlpm.k,_xlfn.XLOOKUP(B11,Parametre!$A$2:$A$7,Parametre!$E$2:$E$7),IF(H11<1,"",MAX(1,ROUND(_xlpm.g*_xlpm.k,0)))) | O11: =_xlfn.LET(_xlpm.g,C11,_xlpm.k,_xlfn.XLOOKUP(B11,Parametre!$A$2:$A$7,Parametre!$F$2:$F$7),IF(H11<2,"",MAX(1,ROUND(_xlpm.g*_xlpm.k,0)))) | P11: =_xlfn.LET(_xlpm.g,C11,_xlpm.s,J11,_xlpm.t,L11,1-_xlpm.g*_xlpm.s/_xlpm.t) | Q11: =_xlfn.LET(_xlpm.m,P11,IF(_xlpm.m>=0.45,3,IF(_xlpm.m>=0.2,2,1)))
A12: L11 | B12: Tanıtım | C12: 29 | D12: 2.85 | E12: 0 | G12: 0 | H12: 0 | I12: 45 | J12: =_xlfn.LET(_xlpm.r,D12,_xlpm.b,E12,_xlpm.f,G12,IF(_xlpm.f=1,1.35,0.6+0.16*_xlpm.r+IF(_xlpm.b>0,0.1,0))) | K12: =_xlfn.XLOOKUP(B12,Parametre!$A$2:$A$7,Parametre!$C$2:$C$7) | L12: =_xlfn.LET(_xlpm.g,C12,_xlpm.s,J12,_xlpm.p,K12,MIN(75,_xlfn.CEILING.MATH(_xlpm.g*_xlpm.s*_xlpm.p,5))) | M12: =IF(E12=0,"",F12+_xlfn.XLOOKUP(B12,Parametre!$A$2:$A$7,Parametre!$D$2:$D$7)) | N12: =_xlfn.LET(_xlpm.g,C12,_xlpm.k,_xlfn.XLOOKUP(B12,Parametre!$A$2:$A$7,Parametre!$E$2:$E$7),IF(H12<1,"",MAX(1,ROUND(_xlpm.g*_xlpm.k,0)))) | O12: =_xlfn.LET(_xlpm.g,C12,_xlpm.k,_xlfn.XLOOKUP(B12,Parametre!$A$2:$A$7,Parametre!$F$2:$F$7),IF(H12<2,"",MAX(1,ROUND(_xlpm.g*_xlpm.k,0)))) | P12: =_xlfn.LET(_xlpm.g,C12,_xlpm.s,J12,_xlpm.t,L12,1-_xlpm.g*_xlpm.s/_xlpm.t) | Q12: =_xlfn.LET(_xlpm.m,P12,IF(_xlpm.m>=0.45,3,IF(_xlpm.m>=0.2,2,1)))
A13: L12 | B13: Kolay | C13: 29 | D13: 2.652 | E13: 0 | G13: 0 | H13: 0 | I13: 40 | J13: =_xlfn.LET(_xlpm.r,D13,_xlpm.b,E13,_xlpm.f,G13,IF(_xlpm.f=1,1.35,0.6+0.16*_xlpm.r+IF(_xlpm.b>0,0.1,0))) | K13: =_xlfn.XLOOKUP(B13,Parametre!$A$2:$A$7,Parametre!$C$2:$C$7) | L13: =_xlfn.LET(_xlpm.g,C13,_xlpm.s,J13,_xlpm.p,K13,MIN(75,_xlfn.CEILING.MATH(_xlpm.g*_xlpm.s*_xlpm.p,5))) | M13: =IF(E13=0,"",F13+_xlfn.XLOOKUP(B13,Parametre!$A$2:$A$7,Parametre!$D$2:$D$7)) | N13: =_xlfn.LET(_xlpm.g,C13,_xlpm.k,_xlfn.XLOOKUP(B13,Parametre!$A$2:$A$7,Parametre!$E$2:$E$7),IF(H13<1,"",MAX(1,ROUND(_xlpm.g*_xlpm.k,0)))) | O13: =_xlfn.LET(_xlpm.g,C13,_xlpm.k,_xlfn.XLOOKUP(B13,Parametre!$A$2:$A$7,Parametre!$F$2:$F$7),IF(H13<2,"",MAX(1,ROUND(_xlpm.g*_xlpm.k,0)))) | P13: =_xlfn.LET(_xlpm.g,C13,_xlpm.s,J13,_xlpm.t,L13,1-_xlpm.g*_xlpm.s/_xlpm.t) | Q13: =_xlfn.LET(_xlpm.m,P13,IF(_xlpm.m>=0.45,3,IF(_xlpm.m>=0.2,2,1)))
... A21: L20 | B21: Orta | C21: 40 | D21: 3.228 | E21: 0 | G21: 0 | H21: 2 | I21: 55 | J21: =_xlfn.LET(_xlpm.r,D21,_xlpm.b,E21,_xlpm.f,G21,IF(_xlpm.f=1,1.35,0.6+0.16*_xlpm.r+IF(_xlpm.b>0,0.1,0))) | K21: =_xlfn.XLOOKUP(B21,Parametre!$A$2:$A$7,Parametre!$C$2:$C$7) | L21: =_xlfn.LET(_xlpm.g,C21,_xlpm.s,J21,_xlpm.p,K21,MIN(75,_xlfn.CEILING.MATH(_xlpm.g*_xlpm.s*_xlpm.p,5))) | M21: =IF(E21=0,"",F21+_xlfn.XLOOKUP(B21,Parametre!$A$2:$A$7,Parametre!$D$2:$D$7)) | N21: =_xlfn.LET(_xlpm.g,C21,_xlpm.k,_xlfn.XLOOKUP(B21,Parametre!$A$2:$A$7,Parametre!$E$2:$E$7),IF(H21<1,"",MAX(1,ROUND(_xlpm.g*_xlpm.k,0)))) | O21: =_xlfn.LET(_xlpm.g,C21,_xlpm.k,_xlfn.XLOOKUP(B21,Parametre!$A$2:$A$7,Parametre!$F$2:$F$7),IF(H21<2,"",MAX(1,ROUND(_xlpm.g*_xlpm.k,0)))) | P21: =_xlfn.LET(_xlpm.g,C21,_xlpm.s,J21,_xlpm.t,L21,1-_xlpm.g*_xlpm.s/_xlpm.t) | Q21: =_xlfn.LET(_xlpm.m,P21,IF(_xlpm.m>=0.45,3,IF(_xlpm.m>=0.2,2,1)))
A22: L21 | B22: Tanıtım | C22: 30 | D22: 2.889 | E22: 1 | F22: 6 | G22: 0 | H22: 0 | I22: 45 | J22: =_xlfn.LET(_xlpm.r,D22,_xlpm.b,E22,_xlpm.f,G22,IF(_xlpm.f=1,1.35,0.6+0.16*_xlpm.r+IF(_xlpm.b>0,0.1,0))) | K22: =_xlfn.XLOOKUP(B22,Parametre!$A$2:$A$7,Parametre!$C$2:$C$7) | L22: =_xlfn.LET(_xlpm.g,C22,_xlpm.s,J22,_xlpm.p,K22,MIN(75,_xlfn.CEILING.MATH(_xlpm.g*_xlpm.s*_xlpm.p,5))) | M22: =IF(E22=0,"",F22+_xlfn.XLOOKUP(B22,Parametre!$A$2:$A$7,Parametre!$D$2:$D$7)) | N22: =_xlfn.LET(_xlpm.g,C22,_xlpm.k,_xlfn.XLOOKUP(B22,Parametre!$A$2:$A$7,Parametre!$E$2:$E$7),IF(H22<1,"",MAX(1,ROUND(_xlpm.g*_xlpm.k,0)))) | O22: =_xlfn.LET(_xlpm.g,C22,_xlpm.k,_xlfn.XLOOKUP(B22,Parametre!$A$2:$A$7,Parametre!$F$2:$F$7),IF(H22<2,"",MAX(1,ROUND(_xlpm.g*_xlpm.k,0)))) | P22: =_xlfn.LET(_xlpm.g,C22,_xlpm.s,J22,_xlpm.t,L22,1-_xlpm.g*_xlpm.s/_xlpm.t) | Q22: =_xlfn.LET(_xlpm.m,P22,IF(_xlpm.m>=0.45,3,IF(_xlpm.m>=0.2,2,1)))
A23: L22 | B23: Zor | C23: 36 | D23: 3.656 | E23: 1 | F23: 7 | G23: 0 | H23: 0 | I23: 55 | J23: =_xlfn.LET(_xlpm.r,D23,_xlpm.b,E23,_xlpm.f,G23,IF(_xlpm.f=1,1.35,0.6+0.16*_xlpm.r+IF(_xlpm.b>0,0.1,0))) | K23: =_xlfn.XLOOKUP(B23,Parametre!$A$2:$A$7,Parametre!$C$2:$C$7) | L23: =_xlfn.LET(_xlpm.g,C23,_xlpm.s,J23,_xlpm.p,K23,MIN(75,_xlfn.CEILING.MATH(_xlpm.g*_xlpm.s*_xlpm.p,5))) | M23: =IF(E23=0,"",F23+_xlfn.XLOOKUP(B23,Parametre!$A$2:$A$7,Parametre!$D$2:$D$7)) | N23: =_xlfn.LET(_xlpm.g,C23,_xlpm.k,_xlfn.XLOOKUP(B23,Parametre!$A$2:$A$7,Parametre!$E$2:$E$7),IF(H23<1,"",MAX(1,ROUND(_xlpm.g*_xlpm.k,0)))) | O23: =_xlfn.LET(_xlpm.g,C23,_xlpm.k,_xlfn.XLOOKUP(B23,Parametre!$A$2:$A$7,Parametre!$F$2:$F$7),IF(H23<2,"",MAX(1,ROUND(_xlpm.g*_xlpm.k,0)))) | P23: =_xlfn.LET(_xlpm.g,C23,_xlpm.s,J23,_xlpm.t,L23,1-_xlpm.g*_xlpm.s/_xlpm.t) | Q23: =_xlfn.LET(_xlpm.m,P23,IF(_xlpm.m>=0.45,3,IF(_xlpm.m>=0.2,2,1)))
A24: L23 | B24: Orta | C24: 35 | D24: 3.029 | E24: 1 | F24: 3 | G24: 0 | H24: 1 | I24: 50 | J24: =_xlfn.LET(_xlpm.r,D24,_xlpm.b,E24,_xlpm.f,G24,IF(_xlpm.f=1,1.35,0.6+0.16*_xlpm.r+IF(_xlpm.b>0,0.1,0))) | K24: =_xlfn.XLOOKUP(B24,Parametre!$A$2:$A$7,Parametre!$C$2:$C$7) | L24: =_xlfn.LET(_xlpm.g,C24,_xlpm.s,J24,_xlpm.p,K24,MIN(75,_xlfn.CEILING.MATH(_xlpm.g*_xlpm.s*_xlpm.p,5))) | M24: =IF(E24=0,"",F24+_xlfn.XLOOKUP(B24,Parametre!$A$2:$A$7,Parametre!$D$2:$D$7)) | N24: =_xlfn.LET(_xlpm.g,C24,_xlpm.k,_xlfn.XLOOKUP(B24,Parametre!$A$2:$A$7,Parametre!$E$2:$E$7),IF(H24<1,"",MAX(1,ROUND(_xlpm.g*_xlpm.k,0)))) | O24: =_xlfn.LET(_xlpm.g,C24,_xlpm.k,_xlfn.XLOOKUP(B24,Parametre!$A$2:$A$7,Parametre!$F$2:$F$7),IF(H24<2,"",MAX(1,ROUND(_xlpm.g*_xlpm.k,0)))) | P24: =_xlfn.LET(_xlpm.g,C24,_xlpm.s,J24,_xlpm.t,L24,1-_xlpm.g*_xlpm.s/_xlpm.t) | Q24: =_xlfn.LET(_xlpm.m,P24,IF(_xlpm.m>=0.45,3,IF(_xlpm.m>=0.2,2,1)))
A25: L24 | B25: Zor | C25: 34 | D25: 3.712 | E25: 1 | F25: 5 | G25: 0 | H25: 2 | I25: 55 | J25: =_xlfn.LET(_xlpm.r,D25,_xlpm.b,E25,_xlpm.f,G25,IF(_xlpm.f=1,1.35,0.6+0.16*_xlpm.r+IF(_xlpm.b>0,0.1,0))) | K25: =_xlfn.XLOOKUP(B25,Parametre!$A$2:$A$7,Parametre!$C$2:$C$7) | L25: =_xlfn.LET(_xlpm.g,C25,_xlpm.s,J25,_xlpm.p,K25,MIN(75,_xlfn.CEILING.MATH(_xlpm.g*_xlpm.s*_xlpm.p,5))) | M25: =IF(E25=0,"",F25+_xlfn.XLOOKUP(B25,Parametre!$A$2:$A$7,Parametre!$D$2:$D$7)) | N25: =_xlfn.LET(_xlpm.g,C25,_xlpm.k,_xlfn.XLOOKUP(B25,Parametre!$A$2:$A$7,Parametre!$E$2:$E$7),IF(H25<1,"",MAX(1,ROUND(_xlpm.g*_xlpm.k,0)))) | O25: =_xlfn.LET(_xlpm.g,C25,_xlpm.k,_xlfn.XLOOKUP(B25,Parametre!$A$2:$A$7,Parametre!$F$2:$F$7),IF(H25<2,"",MAX(1,ROUND(_xlpm.g*_xlpm.k,0)))) | P25: =_xlfn.LET(_xlpm.g,C25,_xlpm.s,J25,_xlpm.t,L25,1-_xlpm.g*_xlpm.s/_xlpm.t) | Q25: =_xlfn.LET(_xlpm.m,P25,IF(_xlpm.m>=0.45,3,IF(_xlpm.m>=0.2,2,1)))
A26: L25 | B26: Zor | C26: 29 | D26: 3.579 | E26: 1 | F26: 5 | G26: 0 | H26: 1 | I26: 45 | J26: =_xlfn.LET(_xlpm.r,D26,_xlpm.b,E26,_xlpm.f,G26,IF(_xlpm.f=1,1.35,0.6+0.16*_xlpm.r+IF(_xlpm.b>0,0.1,0))) | K26: =_xlfn.XLOOKUP(B26,Parametre!$A$2:$A$7,Parametre!$C$2:$C$7) | L26: =_xlfn.LET(_xlpm.g,C26,_xlpm.s,J26,_xlpm.p,K26,MIN(75,_xlfn.CEILING.MATH(_xlpm.g*_xlpm.s*_xlpm.p,5))) | M26: =IF(E26=0,"",F26+_xlfn.XLOOKUP(B26,Parametre!$A$2:$A$7,Parametre!$D$2:$D$7)) | N26: =_xlfn.LET(_xlpm.g,C26,_xlpm.k,_xlfn.XLOOKUP(B26,Parametre!$A$2:$A$7,Parametre!$E$2:$E$7),IF(H26<1,"",MAX(1,ROUND(_xlpm.g*_xlpm.k,0)))) | O26: =_xlfn.LET(_xlpm.g,C26,_xlpm.k,_xlfn.XLOOKUP(B26,Parametre!$A$2:$A$7,Parametre!$F$2:$F$7),IF(H26<2,"",MAX(1,ROUND(_xlpm.g*_xlpm.k,0)))) | P26: =_xlfn.LET(_xlpm.g,C26,_xlpm.s,J26,_xlpm.t,L26,1-_xlpm.g*_xlpm.s/_xlpm.t) | Q26: =_xlfn.LET(_xlpm.m,P26,IF(_xlpm.m>=0.45,3,IF(_xlpm.m>=0.2,2,1)))
A27: L26 | B27: Orta | C27: 35 | D27: 3.17 | E27: 1 | F27: 14 | G27: 0 | H27: 1 | I27: 50 | J27: =_xlfn.LET(_xlpm.r,D27,_xlpm.b,E27,_xlpm.f,G27,IF(_xlpm.f=1,1.35,0.6+0.16*_xlpm.r+IF(_xlpm.b>0,0.1,0))) | K27: =_xlfn.XLOOKUP(B27,Parametre!$A$2:$A$7,Parametre!$C$2:$C$7) | L27: =_xlfn.LET(_xlpm.g,C27,_xlpm.s,J27,_xlpm.p,K27,MIN(75,_xlfn.CEILING.MATH(_xlpm.g*_xlpm.s*_xlpm.p,5))) | M27: =IF(E27=0,"",F27+_xlfn.XLOOKUP(B27,Parametre!$A$2:$A$7,Parametre!$D$2:$D$7)) | N27: =_xlfn.LET(_xlpm.g,C27,_xlpm.k,_xlfn.XLOOKUP(B27,Parametre!$A$2:$A$7,Parametre!$E$2:$E$7),IF(H27<1,"",MAX(1,ROUND(_xlpm.g*_xlpm.k,0)))) | O27: =_xlfn.LET(_xlpm.g,C27,_xlpm.k,_xlfn.XLOOKUP(B27,Parametre!$A$2:$A$7,Parametre!$F$2:$F$7),IF(H27<2,"",MAX(1,ROUND(_xlpm.g*_xlpm.k,0)))) | P27: =_xlfn.LET(_xlpm.g,C27,_xlpm.s,J27,_xlpm.t,L27,1-_xlpm.g*_xlpm.s/_xlpm.t) | Q27: =_xlfn.LET(_xlpm.m,P27,IF(_xlpm.m>=0.45,3,IF(_xlpm.m>=0.2,2,1)))
A28: L27 | B28: Zor | C28: 34 | D28: 3.373 | E28: 1 | F28: 9 | G28: 0 | H28: 2 | I28: 50 | J28: =_xlfn.LET(_xlpm.r,D28,_xlpm.b,E28,_xlpm.f,G28,IF(_xlpm.f=1,1.35,0.6+0.16*_xlpm.r+IF(_xlpm.b>0,0.1,0))) | K28: =_xlfn.XLOOKUP(B28,Parametre!$A$2:$A$7,Parametre!$C$2:$C$7) | L28: =_xlfn.LET(_xlpm.g,C28,_xlpm.s,J28,_xlpm.p,K28,MIN(75,_xlfn.CEILING.MATH(_xlpm.g*_xlpm.s*_xlpm.p,5))) | M28: =IF(E28=0,"",F28+_xlfn.XLOOKUP(B28,Parametre!$A$2:$A$7,Parametre!$D$2:$D$7)) | N28: =_xlfn.LET(_xlpm.g,C28,_xlpm.k,_xlfn.XLOOKUP(B28,Parametre!$A$2:$A$7,Parametre!$E$2:$E$7),IF(H28<1,"",MAX(1,ROUND(_xlpm.g*_xlpm.k,0)))) | O28: =_xlfn.LET(_xlpm.g,C28,_xlpm.k,_xlfn.XLOOKUP(B28,Parametre!$A$2:$A$7,Parametre!$F$2:$F$7),IF(H28<2,"",MAX(1,ROUND(_xlpm.g*_xlpm.k,0)))) | P28: =_xlfn.LET(_xlpm.g,C28,_xlpm.s,J28,_xlpm.t,L28,1-_xlpm.g*_xlpm.s/_xlpm.t) | Q28: =_xlfn.LET(_xlpm.m,P28,IF(_xlpm.m>=0.45,3,IF(_xlpm.m>=0.2,2,1)))
A29: L28 | B29: Zor | C29: 34 | D29: 3.999 | E29: 2 | F29: 4 | G29: 0 | H29: 2 | I29: 55 | J29: =_xlfn.LET(_xlpm.r,D29,_xlpm.b,E29,_xlpm.f,G29,IF(_xlpm.f=1,1.35,0.6+0.16*_xlpm.r+IF(_xlpm.b>0,0.1,0))) | K29: =_xlfn.XLOOKUP(B29,Parametre!$A$2:$A$7,Parametre!$C$2:$C$7) | L29: =_xlfn.LET(_xlpm.g,C29,_xlpm.s,J29,_xlpm.p,K29,MIN(75,_xlfn.CEILING.MATH(_xlpm.g*_xlpm.s*_xlpm.p,5))) | M29: =IF(E29=0,"",F29+_xlfn.XLOOKUP(B29,Parametre!$A$2:$A$7,Parametre!$D$2:$D$7)) | N29: =_xlfn.LET(_xlpm.g,C29,_xlpm.k,_xlfn.XLOOKUP(B29,Parametre!$A$2:$A$7,Parametre!$E$2:$E$7),IF(H29<1,"",MAX(1,ROUND(_xlpm.g*_xlpm.k,0)))) | O29: =_xlfn.LET(_xlpm.g,C29,_xlpm.k,_xlfn.XLOOKUP(B29,Parametre!$A$2:$A$7,Parametre!$F$2:$F$7),IF(H29<2,"",MAX(1,ROUND(_xlpm.g*_xlpm.k,0)))) | P29: =_xlfn.LET(_xlpm.g,C29,_xlpm.s,J29,_xlpm.t,L29,1-_xlpm.g*_xlpm.s/_xlpm.t) | Q29: =_xlfn.LET(_xlpm.m,P29,IF(_xlpm.m>=0.45,3,IF(_xlpm.m>=0.2,2,1)))
A30: L29 | B30: Zor | C30: 39 | D30: 3.599 | E30: 1 | F30: 5 | G30: 0 | H30: 2 | I30: 60 | J30: =_xlfn.LET(_xlpm.r,D30,_xlpm.b,E30,_xlpm.f,G30,IF(_xlpm.f=1,1.35,0.6+0.16*_xlpm.r+IF(_xlpm.b>0,0.1,0))) | K30: =_xlfn.XLOOKUP(B30,Parametre!$A$2:$A$7,Parametre!$C$2:$C$7) | L30: =_xlfn.LET(_xlpm.g,C30,_xlpm.s,J30,_xlpm.p,K30,MIN(75,_xlfn.CEILING.MATH(_xlpm.g*_xlpm.s*_xlpm.p,5))) | M30: =IF(E30=0,"",F30+_xlfn.XLOOKUP(B30,Parametre!$A$2:$A$7,Parametre!$D$2:$D$7)) | N30: =_xlfn.LET(_xlpm.g,C30,_xlpm.k,_xlfn.XLOOKUP(B30,Parametre!$A$2:$A$7,Parametre!$E$2:$E$7),IF(H30<1,"",MAX(1,ROUND(_xlpm.g*_xlpm.k,0)))) | O30: =_xlfn.LET(_xlpm.g,C30,_xlpm.k,_xlfn.XLOOKUP(B30,Parametre!$A$2:$A$7,Parametre!$F$2:$F$7),IF(H30<2,"",MAX(1,ROUND(_xlpm.g*_xlpm.k,0)))) | P30: =_xlfn.LET(_xlpm.g,C30,_xlpm.s,J30,_xlpm.t,L30,1-_xlpm.g*_xlpm.s/_xlpm.t) | Q30: =_xlfn.LET(_xlpm.m,P30,IF(_xlpm.m>=0.45,3,IF(_xlpm.m>=0.2,2,1)))
A31: L30 | B31: Zor | C31: 35 | D31: 3.424 | E31: 1 | F31: 10 | G31: 0 | H31: 1 | I31: 55 | J31: =_xlfn.LET(_xlpm.r,D31,_xlpm.b,E31,_xlpm.f,G31,IF(_xlpm.f=1,1.35,0.6+0.16*_xlpm.r+IF(_xlpm.b>0,0.1,0))) | K31: =_xlfn.XLOOKUP(B31,Parametre!$A$2:$A$7,Parametre!$C$2:$C$7) | L31: =_xlfn.LET(_xlpm.g,C31,_xlpm.s,J31,_xlpm.p,K31,MIN(75,_xlfn.CEILING.MATH(_xlpm.g*_xlpm.s*_xlpm.p,5))) | M31: =IF(E31=0,"",F31+_xlfn.XLOOKUP(B31,Parametre!$A$2:$A$7,Parametre!$D$2:$D$7)) | N31: =_xlfn.LET(_xlpm.g,C31,_xlpm.k,_xlfn.XLOOKUP(B31,Parametre!$A$2:$A$7,Parametre!$E$2:$E$7),IF(H31<1,"",MAX(1,ROUND(_xlpm.g*_xlpm.k,0)))) | O31: =_xlfn.LET(_xlpm.g,C31,_xlpm.k,_xlfn.XLOOKUP(B31,Parametre!$A$2:$A$7,Parametre!$F$2:$F$7),IF(H31<2,"",MAX(1,ROUND(_xlpm.g*_xlpm.k,0)))) | P31: =_xlfn.LET(_xlpm.g,C31,_xlpm.s,J31,_xlpm.t,L31,1-_xlpm.g*_xlpm.s/_xlpm.t) | Q31: =_xlfn.LET(_xlpm.m,P31,IF(_xlpm.m>=0.45,3,IF(_xlpm.m>=0.2,2,1)))
A32: L31 | B32: Tanıtım | C32: 30 | D32: 2.908 | E32: 0 | G32: 0 | H32: 0 | I32: 45 | J32: =_xlfn.LET(_xlpm.r,D32,_xlpm.b,E32,_xlpm.f,G32,IF(_xlpm.f=1,1.35,0.6+0.16*_xlpm.r+IF(_xlpm.b>0,0.1,0))) | K32: =_xlfn.XLOOKUP(B32,Parametre!$A$2:$A$7,Parametre!$C$2:$C$7) | L32: =_xlfn.LET(_xlpm.g,C32,_xlpm.s,J32,_xlpm.p,K32,MIN(75,_xlfn.CEILING.MATH(_xlpm.g*_xlpm.s*_xlpm.p,5))) | M32: =IF(E32=0,"",F32+_xlfn.XLOOKUP(B32,Parametre!$A$2:$A$7,Parametre!$D$2:$D$7)) | N32: =_xlfn.LET(_xlpm.g,C32,_xlpm.k,_xlfn.XLOOKUP(B32,Parametre!$A$2:$A$7,Parametre!$E$2:$E$7),IF(H32<1,"",MAX(1,ROUND(_xlpm.g*_xlpm.k,0)))) | O32: =_xlfn.LET(_xlpm.g,C32,_xlpm.k,_xlfn.XLOOKUP(B32,Parametre!$A$2:$A$7,Parametre!$F$2:$F$7),IF(H32<2,"",MAX(1,ROUND(_xlpm.g*_xlpm.k,0)))) | P32: =_xlfn.LET(_xlpm.g,C32,_xlpm.s,J32,_xlpm.t,L32,1-_xlpm.g*_xlpm.s/_xlpm.t) | Q32: =_xlfn.LET(_xlpm.m,P32,IF(_xlpm.m>=0.45,3,IF(_xlpm.m>=0.2,2,1)))
A33: L32 | B33: Zor | C33: 36 | D33: 3.738 | E33: 0 | G33: 0 | H33: 1 | I33: 55 | J33: =_xlfn.LET(_xlpm.r,D33,_xlpm.b,E33,_xlpm.f,G33,IF(_xlpm.f=1,1.35,0.6+0.16*_xlpm.r+IF(_xlpm.b>0,0.1,0))) | K33: =_xlfn.XLOOKUP(B33,Parametre!$A$2:$A$7,Parametre!$C$2:$C$7) | L33: =_xlfn.LET(_xlpm.g,C33,_xlpm.s,J33,_xlpm.p,K33,MIN(75,_xlfn.CEILING.MATH(_xlpm.g*_xlpm.s*_xlpm.p,5))) | M33: =IF(E33=0,"",F33+_xlfn.XLOOKUP(B33,Parametre!$A$2:$A$7,Parametre!$D$2:$D$7)) | N33: =_xlfn.LET(_xlpm.g,C33,_xlpm.k,_xlfn.XLOOKUP(B33,Parametre!$A$2:$A$7,Parametre!$E$2:$E$7),IF(H33<1,"",MAX(1,ROUND(_xlpm.g*_xlpm.k,0)))) | O33: =_xlfn.LET(_xlpm.g,C33,_xlpm.k,_xlfn.XLOOKUP(B33,Parametre!$A$2:$A$7,Parametre!$F$2:$F$7),IF(H33<2,"",MAX(1,ROUND(_xlpm.g*_xlpm.k,0)))) | P33: =_xlfn.LET(_xlpm.g,C33,_xlpm.s,J33,_xlpm.t,L33,1-_xlpm.g*_xlpm.s/_xlpm.t) | Q33: =_xlfn.LET(_xlpm.m,P33,IF(_xlpm.m>=0.45,3,IF(_xlpm.m>=0.2,2,1)))
A34: L33 | B34: Zor | C34: 35 | D34: 3.34 | E34: 0 | G34: 0 | H34: 1 | I34: 50 | J34: =_xlfn.LET(_xlpm.r,D34,_xlpm.b,E34,_xlpm.f,G34,IF(_xlpm.f=1,1.35,0.6+0.16*_xlpm.r+IF(_xlpm.b>0,0.1,0))) | K34: =_xlfn.XLOOKUP(B34,Parametre!$A$2:$A$7,Parametre!$C$2:$C$7) | L34: =_xlfn.LET(_xlpm.g,C34,_xlpm.s,J34,_xlpm.p,K34,MIN(75,_xlfn.CEILING.MATH(_xlpm.g*_xlpm.s*_xlpm.p,5))) | M34: =IF(E34=0,"",F34+_xlfn.XLOOKUP(B34,Parametre!$A$2:$A$7,Parametre!$D$2:$D$7)) | N34: =_xlfn.LET(_xlpm.g,C34,_xlpm.k,_xlfn.XLOOKUP(B34,Parametre!$A$2:$A$7,Parametre!$E$2:$E$7),IF(H34<1,"",MAX(1,ROUND(_xlpm.g*_xlpm.k,0)))) | O34: =_xlfn.LET(_xlpm.g,C34,_xlpm.k,_xlfn.XLOOKUP(B34,Parametre!$A$2:$A$7,Parametre!$F$2:$F$7),IF(H34<2,"",MAX(1,ROUND(_xlpm.g*_xlpm.k,0)))) | P34: =_xlfn.LET(_xlpm.g,C34,_xlpm.s,J34,_xlpm.t,L34,1-_xlpm.g*_xlpm.s/_xlpm.t) | Q34: =_xlfn.LET(_xlpm.m,P34,IF(_xlpm.m>=0.45,3,IF(_xlpm.m>=0.2,2,1)))
A35: L34 | B35: Çok zor | C35: 35 | D35: 4.007 | E35: 1 | F35: 14 | G35: 0 | H35: 1 | I35: 55 | J35: =_xlfn.LET(_xlpm.r,D35,_xlpm.b,E35,_xlpm.f,G35,IF(_xlpm.f=1,1.35,0.6+0.16*_xlpm.r+IF(_xlpm.b>0,0.1,0))) | K35: =_xlfn.XLOOKUP(B35,Parametre!$A$2:$A$7,Parametre!$C$2:$C$7) | L35: =_xlfn.LET(_xlpm.g,C35,_xlpm.s,J35,_xlpm.p,K35,MIN(75,_xlfn.CEILING.MATH(_xlpm.g*_xlpm.s*_xlpm.p,5))) | M35: =IF(E35=0,"",F35+_xlfn.XLOOKUP(B35,Parametre!$A$2:$A$7,Parametre!$D$2:$D$7)) | N35: =_xlfn.LET(_xlpm.g,C35,_xlpm.k,_xlfn.XLOOKUP(B35,Parametre!$A$2:$A$7,Parametre!$E$2:$E$7),IF(H35<1,"",MAX(1,ROUND(_xlpm.g*_xlpm.k,0)))) | O35: =_xlfn.LET(_xlpm.g,C35,_xlpm.k,_xlfn.XLOOKUP(B35,Parametre!$A$2:$A$7,Parametre!$F$2:$F$7),IF(H35<2,"",MAX(1,ROUND(_xlpm.g*_xlpm.k,0)))) | P35: =_xlfn.LET(_xlpm.g,C35,_xlpm.s,J35,_xlpm.t,L35,1-_xlpm.g*_xlpm.s/_xlpm.t) | Q35: =_xlfn.LET(_xlpm.m,P35,IF(_xlpm.m>=0.45,3,IF(_xlpm.m>=0.2,2,1)))
A36: L35 | B36: Çok zor | C36: 34 | D36: 4.741 | E36: 1 | F36: 5 | G36: 0 | H36: 2 | I36: 60 | J36: =_xlfn.LET(_xlpm.r,D36,_xlpm.b,E36,_xlpm.f,G36,IF(_xlpm.f=1,1.35,0.6+0.16*_xlpm.r+IF(_xlpm.b>0,0.1,0))) | K36: =_xlfn.XLOOKUP(B36,Parametre!$A$2:$A$7,Parametre!$C$2:$C$7) | L36: =_xlfn.LET(_xlpm.g,C36,_xlpm.s,J36,_xlpm.p,K36,MIN(75,_xlfn.CEILING.MATH(_xlpm.g*_xlpm.s*_xlpm.p,5))) | M36: =IF(E36=0,"",F36+_xlfn.XLOOKUP(B36,Parametre!$A$2:$A$7,Parametre!$D$2:$D$7)) | N36: =_xlfn.LET(_xlpm.g,C36,_xlpm.k,_xlfn.XLOOKUP(B36,Parametre!$A$2:$A$7,Parametre!$E$2:$E$7),IF(H36<1,"",MAX(1,ROUND(_xlpm.g*_xlpm.k,0)))) | O36: =_xlfn.LET(_xlpm.g,C36,_xlpm.k,_xlfn.XLOOKUP(B36,Parametre!$A$2:$A$7,Parametre!$F$2:$F$7),IF(H36<2,"",MAX(1,ROUND(_xlpm.g*_xlpm.k,0)))) | P36: =_xlfn.LET(_xlpm.g,C36,_xlpm.s,J36,_xlpm.t,L36,1-_xlpm.g*_xlpm.s/_xlpm.t) | Q36: =_xlfn.LET(_xlpm.m,P36,IF(_xlpm.m>=0.45,3,IF(_xlpm.m>=0.2,2,1)))
A37: L36 | B37: Zor | C37: 29 | D37: 3.639 | E37: 0 | G37: 0 | H37: 1 | I37: 50 | J37: =_xlfn.LET(_xlpm.r,D37,_xlpm.b,E37,_xlpm.f,G37,IF(_xlpm.f=1,1.35,0.6+0.16*_xlpm.r+IF(_xlpm.b>0,0.1,0))) | K37: =_xlfn.XLOOKUP(B37,Parametre!$A$2:$A$7,Parametre!$C$2:$C$7) | L37: =_xlfn.LET(_xlpm.g,C37,_xlpm.s,J37,_xlpm.p,K37,MIN(75,_xlfn.CEILING.MATH(_xlpm.g*_xlpm.s*_xlpm.p,5))) | M37: =IF(E37=0,"",F37+_xlfn.XLOOKUP(B37,Parametre!$A$2:$A$7,Parametre!$D$2:$D$7)) | N37: =_xlfn.LET(_xlpm.g,C37,_xlpm.k,_xlfn.XLOOKUP(B37,Parametre!$A$2:$A$7,Parametre!$E$2:$E$7),IF(H37<1,"",MAX(1,ROUND(_xlpm.g*_xlpm.k,0)))) | O37: =_xlfn.LET(_xlpm.g,C37,_xlpm.k,_xlfn.XLOOKUP(B37,Parametre!$A$2:$A$7,Parametre!$F$2:$F$7),IF(H37<2,"",MAX(1,ROUND(_xlpm.g*_xlpm.k,0)))) | P37: =_xlfn.LET(_xlpm.g,C37,_xlpm.s,J37,_xlpm.t,L37,1-_xlpm.g*_xlpm.s/_xlpm.t) | Q37: =_xlfn.LET(_xlpm.m,P37,IF(_xlpm.m>=0.45,3,IF(_xlpm.m>=0.2,2,1)))
A38: L37 | B38: Orta | C38: 35 | D38: 3.271 | E38: 1 | F38: 2 | G38: 0 | H38: 1 | I38: 55 | J38: =_xlfn.LET(_xlpm.r,D38,_xlpm.b,E38,_xlpm.f,G38,IF(_xlpm.f=1,1.35,0.6+0.16*_xlpm.r+IF(_xlpm.b>0,0.1,0))) | K38: =_xlfn.XLOOKUP(B38,Parametre!$A$2:$A$7,Parametre!$C$2:$C$7) | L38: =_xlfn.LET(_xlpm.g,C38,_xlpm.s,J38,_xlpm.p,K38,MIN(75,_xlfn.CEILING.MATH(_xlpm.g*_xlpm.s*_xlpm.p,5))) | M38: =IF(E38=0,"",F38+_xlfn.XLOOKUP(B38,Parametre!$A$2:$A$7,Parametre!$D$2:$D$7)) | N38: =_xlfn.LET(_xlpm.g,C38,_xlpm.k,_xlfn.XLOOKUP(B38,Parametre!$A$2:$A$7,Parametre!$E$2:$E$7),IF(H38<1,"",MAX(1,ROUND(_xlpm.g*_xlpm.k,0)))) | O38: =_xlfn.LET(_xlpm.g,C38,_xlpm.k,_xlfn.XLOOKUP(B38,Parametre!$A$2:$A$7,Parametre!$F$2:$F$7),IF(H38<2,"",MAX(1,ROUND(_xlpm.g*_xlpm.k,0)))) | P38: =_xlfn.LET(_xlpm.g,C38,_xlpm.s,J38,_xlpm.t,L38,1-_xlpm.g*_xlpm.s/_xlpm.t) | Q38: =_xlfn.LET(_xlpm.m,P38,IF(_xlpm.m>=0.45,3,IF(_xlpm.m>=0.2,2,1)))
A39: L38 | B39: Zor | C39: 35 | D39: 3.699 | E39: 1 | F39: 4 | G39: 0 | H39: 2 | I39: 60 | J39: =_xlfn.LET(_xlpm.r,D39,_xlpm.b,E39,_xlpm.f,G39,IF(_xlpm.f=1,1.35,0.6+0.16*_xlpm.r+IF(_xlpm.b>0,0.1,0))) | K39: =_xlfn.XLOOKUP(B39,Parametre!$A$2:$A$7,Parametre!$C$2:$C$7) | L39: =_xlfn.LET(_xlpm.g,C39,_xlpm.s,J39,_xlpm.p,K39,MIN(75,_xlfn.CEILING.MATH(_xlpm.g*_xlpm.s*_xlpm.p,5))) | M39: =IF(E39=0,"",F39+_xlfn.XLOOKUP(B39,Parametre!$A$2:$A$7,Parametre!$D$2:$D$7)) | N39: =_xlfn.LET(_xlpm.g,C39,_xlpm.k,_xlfn.XLOOKUP(B39,Parametre!$A$2:$A$7,Parametre!$E$2:$E$7),IF(H39<1,"",MAX(1,ROUND(_xlpm.g*_xlpm.k,0)))) | O39: =_xlfn.LET(_xlpm.g,C39,_xlpm.k,_xlfn.XLOOKUP(B39,Parametre!$A$2:$A$7,Parametre!$F$2:$F$7),IF(H39<2,"",MAX(1,ROUND(_xlpm.g*_xlpm.k,0)))) | P39: =_xlfn.LET(_xlpm.g,C39,_xlpm.s,J39,_xlpm.t,L39,1-_xlpm.g*_xlpm.s/_xlpm.t) | Q39: =_xlfn.LET(_xlpm.m,P39,IF(_xlpm.m>=0.45,3,IF(_xlpm.m>=0.2,2,1)))
A40: L39 | B40: Çok zor | C40: 40 | D40: 4.514 | E40: 1 | F40: 3 | G40: 0 | H40: 2 | I40: 70 | J40: =_xlfn.LET(_xlpm.r,D40,_xlpm.b,E40,_xlpm.f,G40,IF(_xlpm.f=1,1.35,0.6+0.16*_xlpm.r+IF(_xlpm.b>0,0.1,0))) | K40: =_xlfn.XLOOKUP(B40,Parametre!$A$2:$A$7,Parametre!$C$2:$C$7) | L40: =_xlfn.LET(_xlpm.g,C40,_xlpm.s,J40,_xlpm.p,K40,MIN(75,_xlfn.CEILING.MATH(_xlpm.g*_xlpm.s*_xlpm.p,5))) | M40: =IF(E40=0,"",F40+_xlfn.XLOOKUP(B40,Parametre!$A$2:$A$7,Parametre!$D$2:$D$7)) | N40: =_xlfn.LET(_xlpm.g,C40,_xlpm.k,_xlfn.XLOOKUP(B40,Parametre!$A$2:$A$7,Parametre!$E$2:$E$7),IF(H40<1,"",MAX(1,ROUND(_xlpm.g*_xlpm.k,0)))) | O40: =_xlfn.LET(_xlpm.g,C40,_xlpm.k,_xlfn.XLOOKUP(B40,Parametre!$A$2:$A$7,Parametre!$F$2:$F$7),IF(H40<2,"",MAX(1,ROUND(_xlpm.g*_xlpm.k,0)))) | P40: =_xlfn.LET(_xlpm.g,C40,_xlpm.s,J40,_xlpm.t,L40,1-_xlpm.g*_xlpm.s/_xlpm.t) | Q40: =_xlfn.LET(_xlpm.m,P40,IF(_xlpm.m>=0.45,3,IF(_xlpm.m>=0.2,2,1)))
A41: L40 | B41: Çok zor | C41: 39 | D41: 4.075 | E41: 2 | F41: 2 | G41: 0 | H41: 2 | I41: 65 | J41: =_xlfn.LET(_xlpm.r,D41,_xlpm.b,E41,_xlpm.f,G41,IF(_xlpm.f=1,1.35,0.6+0.16*_xlpm.r+IF(_xlpm.b>0,0.1,0))) | K41: =_xlfn.XLOOKUP(B41,Parametre!$A$2:$A$7,Parametre!$C$2:$C$7) | L41: =_xlfn.LET(_xlpm.g,C41,_xlpm.s,J41,_xlpm.p,K41,MIN(75,_xlfn.CEILING.MATH(_xlpm.g*_xlpm.s*_xlpm.p,5))) | M41: =IF(E41=0,"",F41+_xlfn.XLOOKUP(B41,Parametre!$A$2:$A$7,Parametre!$D$2:$D$7)) | N41: =_xlfn.LET(_xlpm.g,C41,_xlpm.k,_xlfn.XLOOKUP(B41,Parametre!$A$2:$A$7,Parametre!$E$2:$E$7),IF(H41<1,"",MAX(1,ROUND(_xlpm.g*_xlpm.k,0)))) | O41: =_xlfn.LET(_xlpm.g,C41,_xlpm.k,_xlfn.XLOOKUP(B41,Parametre!$A$2:$A$7,Parametre!$F$2:$F$7),IF(H41<2,"",MAX(1,ROUND(_xlpm.g*_xlpm.k,0)))) | P41: =_xlfn.LET(_xlpm.g,C41,_xlpm.s,J41,_xlpm.t,L41,1-_xlpm.g*_xlpm.s/_xlpm.t) | Q41: =_xlfn.LET(_xlpm.m,P41,IF(_xlpm.m>=0.45,3,IF(_xlpm.m>=0.2,2,1)))

Sheet Fabrika
A1: Slot | B1: Tür | C1: Yeni | D1: Seviye | E1: Durum | F1: Tahta | G1: Gövde | H1: Süre | I1: P | J1: Okuma | K1: İlk hamlede serbest | L1: Keyif tahmini | M1: Hayal kırıklığı | N1: Sıkıcı | O1: İlk deneme | P1: 3 denemede | Q1: Near-miss | R1: Eğri uyumu
A2: 1 | B2: Tanıtım | D2: C01-2086a88b | E2: finalist | F2: 4×5 | G2: 20 | H2: 60 | I2: 2.22 | J2: 1.65 | K2: 9 | L2: 1 | M2: 0 | N2: 0 | O2: 1 | P2: 1 | Q2: 0.001
A3: 2 | B3: Kolay | D3: C02-9bca8ba7 | E3: finalist | F3: 4×5 | G3: 20 | H3: 35 | I3: 2.04 | J3: 1.62 | K3: 8 | L3: 0.981 | M3: 0.018 | N3: 0.001 | O3: 0.967 | P3: 0.983 | Q3: 0.047
A4: 3 | B4: Tanıtım | C4: çivi | D4: C03-40f02903 | E4: finalist | F4: 5×6 | G4: 30 | H4: 65 | I4: 2.28 | J4: 2.19 | K4: 9 | L4: 0.984 | M4: 0.016 | N4: 0 | O4: 0.984 | P4: 0.996 | Q4: 0.026
A5: 4 | B5: Kolay | D5: C04-047aa68d | E5: finalist | F5: 5×5 | G5: 25 | H5: 45 | I5: 2 | J5: 1.86 | K5: 11 | L5: 0.981 | M5: 0.017 | N5: 0.002 | O5: 0.966 | P5: 0.983 | Q5: 0.039
A6: 5 | B6: Tanıtım | C6: makas | D6: C05-8fcbc1dd | E6: finalist | F6: 5×6 | G6: 30 | H6: 60 | I6: 2.24 | J6: 1.83 | K6: 8 | L6: 0.981 | M6: 0.019 | N6: 0 | O6: 0.981 | P6: 0.993 | Q6: 0.029
A7: 6 | B7: Orta | D7: C06-0f100185 | E7: finalist | F7: 5×6 | G7: 30 | H7: 55 | I7: 1.71 | J7: 2.96 | K7: 6 | L7: 0.954 | M7: 0.046 | N7: 0 | O7: 0.895 | P7: 0.966 | Q7: 0.116 | R7: 0.56
A8: 7 | B8: Tanıtım | C8: mühür | D8: C07-4ef0899b | E8: finalist | F8: 5×6 | G8: 30 | H8: 60 | I8: 2.3 | J8: 1.7 | K8: 12 | L8: 0.985 | M8: 0.015 | N8: 0 | O8: 0.985 | P8: 0.992 | Q8: 0.027
A9: 8 | B9: Kolay | D9: C08-184d7c45 | E9: finalist | F9: 5×6 | G9: 30 | H9: 55 | I9: 2.1 | J9: 1.71 | K9: 10 | L9: 0.983 | M9: 0.017 | N9: 0 | O9: 0.965 | P9: 0.984 | Q9: 0.043
A10: 9 | B10: Tanıtım | C10: değnek | D10: C09-111692a5 | E10: finalist | F10: 5×6 | G10: 30 | H10: 60 | I10: 2.25 | J10: 1.8 | K10: 11 | L10: 0.984 | M10: 0.016 | N10: 0 | O10: 0.984 | P10: 0.993 | Q10: 0.025
A11: 10 | B11: Zor | D11: C10-163b2367 | E11: finalist | F11: 6×6 | G11: 36 | H11: 50 | I11: 1.13 | J11: 3.96 | K11: 7 | L11: 0.773 | M11: 0.227 | N11: 0 | O11: 0.624 | P11: 0.815 | Q11: 0.243 | R11: 0.56
A12: 11 | B12: Nefes | D12: C11-031194a1 | E12: finalist | F12: 5×6 | G12: 30 | H12: 60 | I12: 2.11 | J12: 2.17 | K12: 12 | L12: 0.983 | M12: 0.017 | N12: 0 | O12: 0.955 | P12: 0.985 | Q12: 0.05
A13: 12 | B13: Tanıtım | C13: zincir | D13: C12-782c6447 | E13: finalist | F13: 5×6 | G13: 28 | H13: 55 | I13: 2.27 | J13: 1.66 | K13: 11 | L13: 0.985 | M13: 0.015 | N13: 0 | O13: 0.985 | P13: 0.993 | Q13: 0.031
A14: 13 | B14: Orta | D14: C13-51d0b947 | E14: finalist | F14: 6×6 | G14: 34 | H14: 60 | I14: 1.69 | J14: 2.78 | K14: 8 | L14: 0.955 | M14: 0.045 | N14: 0 | O14: 0.888 | P14: 0.963 | Q14: 0.117 | R14: 0.73
A15: 14 | B15: Zor | D15: C14-bb52f55f | E15: finalist | F15: 6×6 | G15: 35 | H15: 50 | I15: 1.2 | J15: 3.69 | K15: 7 | L15: 0.77 | M15: 0.23 | N15: 0 | O15: 0.641 | P15: 0.826 | Q15: 0.242 | R15: 0.62
A16: 15 | B16: Tanıtım | C16: saat | D16: C15-6d50aae9 | E16: finalist | F16: 5×6 | G16: 30 | H16: 60 | I16: 2.3 | J16: 1.67 | K16: 13 | L16: 0.979 | M16: 0.021 | N16: 0 | O16: 0.979 | P16: 0.993 | Q16: 0.025
A17: 16 | B17: Orta | D17: C16-866b071d | E17: finalist | F17: 6×6 | G17: 34 | H17: 60 | I17: 1.69 | J17: 2.78 | K17: 8 | L17: 0.947 | M17: 0.053 | N17: 0 | O17: 0.895 | P17: 0.96 | Q17: 0.098 | R17: 0.56
A18: 17 | B18: Zor | D18: C17-73ba08a9 | E18: finalist | F18: 6×6 | G18: 33 | H18: 50 | I18: 1.26 | J18: 3.74 | K18: 7 | L18: 0.781 | M18: 0.219 | N18: 0 | O18: 0.648 | P18: 0.848 | Q18: 0.204 | R18: 0.75
A19: 18 | B19: Nefes | D19: C18-1107bea7 | E19: finalist | F19: 5×6 | G19: 29 | H19: 55 | I19: 2.05 | J19: 2.02 | K19: 10 | L19: 0.987 | M19: 0.013 | N19: 0 | O19: 0.965 | P19: 0.988 | Q19: 0.045
A20: 19 | B20: Zor | D20: C19-f6b3e601 | E20: finalist | F20: 6×6 | G20: 33 | H20: 50 | I20: 1.23 | J20: 3.92 | K20: 5 | L20: 0.757 | M20: 0.243 | N20: 0 | O20: 0.63 | P20: 0.841 | Q20: 0.22 | R20: 0.56
A21: 20 | B21: Tanıtım | C21: bomba | D21: C20-45673591 | E21: finalist | F21: 5×6 | G21: 30 | H21: 75 | I21: 2.31 | J21: 2.39 | K21: 9 | L21: 0.979 | M21: 0.021 | N21: 0 | O21: 0.979 | P21: 0.995 | Q21: 0.006
A22: 21 | B22: Kolay | D22: C21-37f1c6f3 | E22: finalist | F22: 5×6 | G22: 30 | H22: 55 | I22: 2.08 | J22: 1.77 | K22: 11 | L22: 0.982 | M22: 0.018 | N22: 0 | O22: 0.965 | P22: 0.984 | Q22: 0.043
A23: 22 | B23: Zor | D23: C22-5614b55b | E23: finalist | F23: 6×6 | G23: 33 | H23: 70 | I23: 1.6 | J23: 3.9 | K23: 5 | L23: 0.841 | M23: 0.159 | N23: 0 | O23: 0.442 | P23: 0.844 | Q23: 0.028 | R23: 0.86
A24: 23 | B24: Tanıtım | C24: çekiç | D24: C23-7cd79db1 | E24: finalist | F24: 5×5 | G24: 25 | H24: 45 | I24: 2.21 | J24: 1.33 | K24: 12 | L24: 0.982 | M24: 0.018 | N24: 0 | O24: 0.982 | P24: 0.991 | Q24: 0.03
A25: 24 | B25: Orta | D25: C24-198d2289 | E25: finalist | F25: 6×6 | G25: 35 | H25: 65 | I25: 1.56 | J25: 3.06 | K25: 8 | L25: 0.958 | M25: 0.042 | N25: 0 | O25: 0.897 | P25: 0.965 | Q25: 0.082 | R25: 0.7
A26: 25 | B26: Zor | D26: C25-24c94cef | E26: finalist | F26: 6×6 | G26: 33 | H26: 75 | I26: 1.71 | J26: 3.93 | K26: 6 | L26: 0.88 | M26: 0.12 | N26: 0 | O26: 0.528 | P26: 0.884 | Q26: 0.027 | R26: 0.61
A27: 26 | B27: Nefes | D27: C26-31e86877 | E27: finalist | F27: 5×6 | G27: 30 | H27: 55 | I27: 2.07 | J27: 1.79 | K27: 12 | L27: 0.986 | M27: 0.014 | N27: 0 | O27: 0.971 | P27: 0.986 | Q27: 0.036
A28: 27 | B28: Orta | D28: C27-71616439 | E28: finalist | F28: 5×6 | G28: 29 | H28: 55 | I28: 1.75 | J28: 3.01 | K28: 8 | L28: 0.946 | M28: 0.054 | N28: 0 | O28: 0.898 | P28: 0.96 | Q28: 0.098 | R28: 1
A29: 28 | B29: Zor | D29: C28-d58077d1 | E29: finalist | F29: 6×6 | G29: 33 | H29: 50 | I29: 1.16 | J29: 3.82 | K29: 7 | L29: 0.77 | M29: 0.23 | N29: 0 | O29: 0.482 | P29: 0.793 | Q29: 0.16 | R29: 0.56
A30: 29 | B30: Nefes | D30: C29-2d9dcde3 | E30: finalist | F30: 5×5 | G30: 25 | H30: 45 | I30: 2.09 | J30: 1.63 | K30: 11 | L30: 0.984 | M30: 0.016 | N30: 0 | O30: 0.965 | P30: 0.984 | Q30: 0.045
A31: 30 | B31: Çok zor | D31: C30-37066ecb | E31: finalist | F31: 6×7 | G31: 39 | H31: 60 | I31: 1.08 | J31: 4.53 | K31: 6 | L31: 0.671 | M31: 0.329 | N31: 0 | O31: 0.336 | P31: 0.706 | Q31: 0.16 | R31: 0.78
A32: 31 | B32: Nefes | D32: C31-ee07d843 | E32: finalist | F32: 4×5 | G32: 20 | H32: 35 | I32: 2.17 | J32: 1.29 | K32: 10 | L32: 0.982 | M32: 0.018 | N32: 0 | O32: 0.967 | P32: 0.982 | Q32: 0.041
A33: 32 | B33: Zor | D33: C32-89d50505 | E33: finalist | F33: 6×6 | G33: 34 | H33: 50 | I33: 1.12 | J33: 3.85 | K33: 7 | L33: 0.795 | M33: 0.205 | N33: 0 | O33: 0.645 | P33: 0.837 | Q33: 0.2 | R33: 0.87
A34: 33 | B34: Orta | D34: C33-18f6ab59 | E34: finalist | F34: 5×6 | G34: 30 | H34: 60 | I34: 1.75 | J34: 2.76 | K34: 7 | L34: 0.956 | M34: 0.044 | N34: 0 | O34: 0.896 | P34: 0.969 | Q34: 0.084 | R34: 0.98
A35: 34 | B35: Çok zor | D35: — | E35: aday yok
A36: 35 | B36: Nefes | D36: C35-9255a195 | E36: finalist | F36: 5×5 | G36: 24 | H36: 40 | I36: 2.03 | J36: 1.37 | K36: 12 | L36: 0.979 | M36: 0.021 | N36: 0 | O36: 0.965 | P36: 0.979 | Q36: 0.036
A37: 36 | B37: Zor | D37: C36-a0e5098d | E37: finalist | F37: 6×6 | G37: 33 | H37: 50 | I37: 1.2 | J37: 3.49 | K37: 7 | L37: 0.785 | M37: 0.215 | N37: 0 | O37: 0.481 | P37: 0.799 | Q37: 0.173 | R37: 1
A38: 37 | B38: Orta | D38: C37-d882b223 | E38: finalist | F38: 6×6 | G38: 36 | H38: 65 | I38: 1.67 | J38: 2.99 | K38: 8 | L38: 0.937 | M38: 0.063 | N38: 0 | O38: 0.872 | P38: 0.951 | Q38: 0.119 | R38: 0.6
A39: 38 | B39: Zor | D39: C38-2935bf97 | E39: finalist | F39: 6×6 | G39: 34 | H39: 65 | I39: 1.43 | J39: 3.98 | K39: 7 | L39: 0.8 | M39: 0.2 | N39: 0 | O39: 0.483 | P39: 0.801 | Q39: 0.047 | R39: 0.78
A40: 39 | B40: Nefes | D40: C39-f54076df | E40: finalist | F40: 5×5 | G40: 24 | H40: 45 | I40: 2.03 | J40: 2.03 | K40: 9 | L40: 0.988 | M40: 0.012 | N40: 0 | O40: 0.966 | P40: 0.988 | Q40: 0.05
...
